<?xml version="1.0"?>

<robot name="my_arm">

    <material name="white">
        <color rgba="1 1 1 1"/>
    </material>

    <material name="green">
        <color rgba="0 0.702 0.173 1"/>
    </material>

    <link name="base_link">
        <visual>
            <geometry>
                <mesh filename="package://my_bot/meshes/base_link.STL" scale="10 10 10"/>
            </geometry>
            <origin rpy="0 0 0" xyz="0 0 0"/>
            <material name="white"/>
        </visual>
    </link>

    <link name="link_1">
        <visual>
            <geometry>
                <mesh filename="package://my_bot/meshes/link_1.STL" scale="10 10 10"/>
            </geometry>
            <origin rpy="0 0 0" xyz="0 0 0"/>
            <material name="green"/>
        </visual>
    </link>

    <link name="link_2">
        <visual>
            <geometry>
                <mesh filename="package://my_bot/meshes/link_2.STL" scale="10 10 10"/>
            </geometry>
            <origin rpy="0 0 0" xyz="0 0 0"/>
            <material name="green"/>
        </visual>
    </link>

    <link name="link_3">
        <visual>
            <geometry>
                <mesh filename="package://my_bot/meshes/link_3.STL" scale="10 10 10"/>
            </geometry>
            <origin rpy="0 0 0" xyz="0 0 0"/>
            <material name="green"/>
        </visual>
    </link>

    <joint name="joint_1" type="revolute">
        <parent link="base_link"/>
        <child link="link_1"/>
        <origin rpy="0 0 0" xyz="0 0 0.625"/>
        <limit lower="-3.14159" upper="3.14159" effort="10" velocity="3"/>
        <axis xyz="0 0 1"/>
    </joint>

    <joint name="joint_2" type="revolute">
        <parent link="link_1"/>
        <child link="link_2"/>
        <origin rpy="1.571 -1.571 0" xyz="0.25 0 0"/>
        <limit lower="-3.14159" upper="3.14159" effort="10" velocity="3"/>
        <axis xyz="0 0 1"/>
    </joint>

    <joint name="joint_3" type="revolute">
        <parent link="link_2"/>
        <child link="link_3"/>
        <origin rpy="0 0 -1.571" xyz="0.4 0 0"/>
        <limit lower="-3.14159" upper="3.14159" effort="10" velocity="3"/>
        <axis xyz="0 0 1"/>
    </joint>
</robot>