<?xml version="1.0"?>
<robot name="myfirst">

  <material name="orange">
    <color rgba="1 0.7 0 1"/>
  </material>

  <material name="white">
    <color rgba="1 1 1 1"/>
  </material>

  <link name="base_link">
    <visual>3
      <geometry>
        <box size = "0.6 0.6 0.2"/>
      </geometry>
      <origin rpy="0 0 0" xyz="0 0 0.15"/>
      <material name="orange"/>
    </visual>
  </link>

  <link name="rear_left">
    <visual>
      <geometry>
        <cylinder radius="0.15" length="0.05"/>
      </geometry>
      <origin rpy="0 0 0" xyz="0 0 0"/>
      <material name="white"/>
    </visual>
  </link>

  <link name="rear_right">
    <visual>
      <geometry>
        <cylinder radius="0.15" length="0.05"/>
      </geometry>
      <origin rpy="0 0 0" xyz="0 0 0"/>
      <material name="white"/>
    </visual>
  </link>
  
  <link name="front_left">
    <visual>
      <geometry>
        <cylinder radius="0.10" length="0.05"/>
      </geometry>
      <origin rpy="0 0 0" xyz="0 0 0"/>
      <material name="white"/>
    </visual>
  </link>

  <link name="front_right">
    <visual>
      <geometry>
        <cylinder radius="0.10" length="0.05"/>
      </geometry>
      <origin rpy="0 0 0" xyz="0 0 0"/>
      <material name="white"/>
    </visual>
  </link>

  <joint name="front_right_link" type="continuous">
    <parent link="base_link"/>
    <child link="front_right"/>
    <origin rpy="-1.57 0 0" xyz="0.2 -0.325 0.1"/>
    <axis xyz="0 0 1"/>
  </joint>

  <joint name="front_left_link" type="continuous">
    <parent link="base_link"/>
    <child link="front_left"/>
    <origin rpy="-1.57 0 0" xyz="0.2 0.325 0.1"/>
    <axis xyz="0 0 1"/>
  </joint>


  <joint name="rear_right_link" type="continuous">
    <parent link="base_link"/>
    <child link="rear_right"/>
    <origin rpy="-1.57 0 0" xyz="-0.2 -0.325 0.15"/>
    <axis xyz="0 0 1"/>
  </joint>

  <joint name="rear_left_link" type="continuous">
    <parent link="base_link"/>
    <child link="rear_left"/>
    <origin rpy="-1.57 0 0" xyz="-0.2 0.325 0.15"/>
    <axis xyz="0 0 1"/>
  </joint>


</robot>