<?xml version="1.0"?>
<robot name="KumaraNeck" xmlns:xacro="http://www.ros.org/wiki/xacro">
    
    <xacro:include filename="$(find kumara_description)/urdf/kumara_properties.xacro" />
    
    <xacro:macro name="kumara_neck" params="parent child">

        <link name="neck_tran_x">
            <inertial>
                <origin rpy="0.0 0 0" xyz="0 0 0"/>
                <mass value="0.001" />
                <inertia ixx="0" ixy="0.0" ixz="0.0" iyy="0" iyz="0.0" izz="0"/>
            </inertial>
            <visual>
                <origin rpy="0.0 0 0" xyz="0 0 0"/>
                <geometry>
                    <box size="0.000001 0.000001 0.000001"/>
                </geometry>
            </visual>
        </link>

        <joint name="neck_tran_x_joint" type="prismatic">
            <origin xyz="0.17887 0 1.194" rpy="0.0 0.0 0.0"/>
            <parent link="${parent}" />
            <child link="neck_tran_x" />
            <axis xyz="1 0 0" />
            <limit effort="10000" lower="-0.059" upper="0.059" velocity="1000" />
            <dynamics damping="2.0" />
        </joint>

        <link name="neck_tran_z">
            <inertial>
                <origin rpy="0.0 0 0" xyz="0 0 0"/>
                <mass value="0.001" />
                <inertia ixx="0" ixy="0.0" ixz="0.0" iyy="0" iyz="0.0" izz="0"/>
            </inertial>
            <visual>
                <origin rpy="0.0 0 0" xyz="0 0 0"/>
                <geometry>
                    <box size="0.000001 0.000001 0.000001"/>
                </geometry>
            </visual>
        </link>

        <joint name="neck_tran_z_joint" type="prismatic">
            <origin xyz="0 0 0" rpy="0.0 0.0 0.0"/>
            <parent link="neck_tran_x" />
            <child link="neck_tran_z" />
            <axis xyz="0 0 1" />
            <limit effort="10000" lower="-0.018" upper="0" velocity="1000" />
            <dynamics damping="2.0" />
        </joint>

        <link name="neck_rot_x">
            <inertial>
                <origin rpy="0.0 0 0" xyz="0 0 0"/>
                <mass value="0.01" />
                <inertia ixx="0" ixy="0.0" ixz="0.0" iyy="0" iyz="0.0" izz="0"/>
            </inertial>
            <visual>
                <origin rpy="0.0 0 0" xyz="0 0 0"/>
                <geometry>
                    <box size="0.000001 0.000001 0.000001"/>
                </geometry>
            </visual>
        </link>

        <joint name="neck_rot_x_joint" type="revolute">
            <origin xyz="0 0 0" rpy="0.0 0.0 0.0"/>
            <parent link="neck_tran_z" />
            <child link="neck_rot_x" />
            <axis xyz="1 0 0" />
            <limit effort="10000" lower="-1.0472" upper="1.0472" velocity="1000" />
            <dynamics damping="2.0" />
        </joint>

            <link name="neck_rot_y">
            <inertial>
                <origin rpy="0.0 0 0" xyz="0 0 0"/>
                <mass value="0.01" />
                <inertia ixx="0" ixy="0.0" ixz="0.0" iyy="0" iyz="0.0" izz="0"/>
            </inertial>
            <visual>
                <origin rpy="0.0 0 0" xyz="0 0 0"/>
                <geometry>
                    <box size="0.000001 0.000001 0.000001"/>
                </geometry>
            </visual>
        </link>

        <joint name="neck_rot_y_joint" type="revolute">
            <origin xyz="0 0 0" rpy="0.0 0.0 0.0"/>
            <parent link="neck_rot_x" />
            <child link="neck_rot_y" />
            <axis xyz="0 1 0" />
            <limit effort="10000" lower="-1.0472" upper="1.0472" velocity="1000" />
            <dynamics damping="2.0" />
        </joint>

        <link name="neck_rot_z">
            <inertial>
                <origin rpy="0.0 0 0" xyz="0 0 0"/>
                <mass value="0.01" />
                <inertia ixx="0" ixy="0.0" ixz="0.0" iyy="0" iyz="0.0" izz="0"/>
            </inertial>
            <visual>
                <origin rpy="0.0 0 0" xyz="0 0 0"/>
                <geometry>
                    <box size="0.000001 0.000001 0.000001"/>
                </geometry>
            </visual>
        </link>

        <joint name="neck_rot_z_joint" type="revolute">
            <origin xyz="0 0 0" rpy="0.0 0.0 0.0"/>
            <parent link="neck_rot_y" />
            <child link="neck_rot_z" />
            <axis xyz="0 0 1" />
            <limit effort="10000" lower="-${PI}" upper="${PI}" velocity="1000" />
            <dynamics damping="2.0" />
        </joint>

        <joint name="neck_to_${child}" type="fixed">
            <parent link="neck_rot_z"/>
            <child link="${child}"/>
            <origin xyz="0 0 0"/>
        </joint>

        <transmission name="tran_neck_x">
            <type>transmission_interface/SimpleTransmission</type>
            <joint name="neck_tran_x_joint">
                <hardwareInterface>hardware_interface/EffortJointInterface</hardwareInterface>
            </joint>
            <actuator name="neck_motor_x">
                <hardwareInterface>hardware_interface/EffortJointInterface</hardwareInterface>
                <mechanicalReduction>1</mechanicalReduction>
            </actuator>
        </transmission>

        <transmission name="tran_neck_z">
            <type>transmission_interface/SimpleTransmission</type>
            <joint name="neck_tran_z_joint">
                <hardwareInterface>hardware_interface/EffortJointInterface</hardwareInterface>
            </joint>
            <actuator name="neck_motor_z">
                <hardwareInterface>hardware_interface/EffortJointInterface</hardwareInterface>
                <mechanicalReduction>1</mechanicalReduction>
            </actuator>
        </transmission>
        
        <transmission name="tran_neck_rx">
            <type>transmission_interface/SimpleTransmission</type>
            <joint name="neck_rot_x_joint">
                <hardwareInterface>hardware_interface/EffortJointInterface</hardwareInterface>
            </joint>
            <actuator name="neck_motor_rx">
                <hardwareInterface>hardware_interface/EffortJointInterface</hardwareInterface>
                <mechanicalReduction>1</mechanicalReduction>
            </actuator>
        </transmission>

        <transmission name="tran_neck_ry">
            <type>transmission_interface/SimpleTransmission</type>
            <joint name="neck_rot_y_joint">
                <hardwareInterface>hardware_interface/EffortJointInterface</hardwareInterface>
            </joint>
            <actuator name="neck_motor_ry">
                <hardwareInterface>hardware_interface/EffortJointInterface</hardwareInterface>
                <mechanicalReduction>1</mechanicalReduction>
            </actuator>
        </transmission>

        <transmission name="tran_neck_rz">
            <type>transmission_interface/SimpleTransmission</type>
            <joint name="neck_rot_z_joint">
                <hardwareInterface>hardware_interface/EffortJointInterface</hardwareInterface>
            </joint>
            <actuator name="neck_motor_rz">
                <hardwareInterface>hardware_interface/EffortJointInterface</hardwareInterface>
                <mechanicalReduction>1</mechanicalReduction>
            </actuator>
        </transmission>
        
    </xacro:macro>
</robot>